<robot name="onshape">
<link name="gear2ok">
<visual>
<origin xyz="0.020272936709822289569 0.061486230867351318596 0.094140773333058522243" rpy="1.570796326794896558 1.1623751634378201025 -7.2004099377063500379e-16" />
<geometry>
<mesh filename="package:///grip_finger1.stl"/>
</geometry>
<material name="grip_finger1_material">
<color rgba="0.97254901960784312376 0.52941176470588235947 0.0039215686274509803377 1.0"/>
</material>
</visual>
<collision>
<origin xyz="0.020272936709822289569 0.061486230867351318596 0.094140773333058522243" rpy="1.570796326794896558 1.1623751634378201025 -7.2004099377063500379e-16" />
<geometry>
<mesh filename="package:///grip_finger1.stl"/>
</geometry>
</collision>
<visual>
<origin xyz="0.011538563847797403406 0.048986230215425509427 0.051699395727593508432" rpy="1.570796326794896558 1.036528381382468611 3.141592653589793116" />
<geometry>
<mesh filename="package:///gear2ok.stl"/>
</geometry>
<material name="gear2ok_material">
<color rgba="0.64705882352941179736 0.64705882352941179736 0.64705882352941179736 1.0"/>
</material>
</visual>
<collision>
<origin xyz="0.011538563847797403406 0.048986230215425509427 0.051699395727593508432" rpy="1.570796326794896558 1.036528381382468611 3.141592653589793116" />
<geometry>
<mesh filename="package:///gear2ok.stl"/>
</geometry>
</collision>
<inertial>
<origin xyz="0.019958931611641080733 0.057236230636383327031 0.093162867458307901947" rpy="0 0 0"/>
<mass value="0.0067468279681199561093" />
<inertia ixx="2.0576331358039405955e-06" ixy="-3.8053209294571710784e-22"  ixz="3.2390742910256535117e-07" iyy="2.1436393192487343099e-06" iyz="-3.4697104653663527641e-23" izz="1.6724924572443020189e-07" />
</inertial>
</link>

<link name="link_palm">
<visual>
<origin xyz="-0.026625746457587449317 -0.033438409341413205533 0.0040000001899898052216" rpy="-3.141592653589793116 8.5793248054355562542e-17 1.0490284188767595719" />
<geometry>
<mesh filename="package:///grip_link.stl"/>
</geometry>
<material name="grip_link_material">
<color rgba="0.97254901960784312376 0.52941176470588235947 0.0039215686274509803377 1.0"/>
</material>
</visual>
<collision>
<origin xyz="-0.026625746457587449317 -0.033438409341413205533 0.0040000001899898052216" rpy="-3.141592653589793116 8.5793248054355562542e-17 1.0490284188767595719" />
<geometry>
<mesh filename="package:///grip_link.stl"/>
</geometry>
</collision>
<visual>
<origin xyz="-0.031899999615699871358 0.051999995325182499228 -0.028000000864267352713" rpy="1.570796326794896558 -0 0" />
<geometry>
<mesh filename="package:///link_palm.stl"/>
</geometry>
<material name="link_palm_material">
<color rgba="0.64705882352941179736 0.64705882352941179736 0.64705882352941179736 1.0"/>
</material>
</visual>
<collision>
<origin xyz="-0.031899999615699871358 0.051999995325182499228 -0.028000000864267352713" rpy="1.570796326794896558 -0 0" />
<geometry>
<mesh filename="package:///link_palm.stl"/>
</geometry>
</collision>
<visual>
<origin xyz="0.00067080609260291960971 -0.032193253054723730555 0.0040000001899898052216" rpy="3.141592653589793116 -4.955537189457148445e-17 -0.90531673254266897821" />
<geometry>
<mesh filename="package:///grip_link.stl"/>
</geometry>
<material name="grip_link_material">
<color rgba="0.97254901960784312376 0.52941176470588235947 0.0039215686274509803377 1.0"/>
</material>
</visual>
<collision>
<origin xyz="0.00067080609260291960971 -0.032193253054723730555 0.0040000001899898052216" rpy="3.141592653589793116 -4.955537189457148445e-17 -0.90531673254266897821" />
<geometry>
<mesh filename="package:///grip_link.stl"/>
</geometry>
</collision>
<inertial>
<origin xyz="-0.015302247930950366867 0.0096593941905146665089 -0.0070816423179647751407" rpy="0 0 0"/>
<mass value="0.022499869934744811534" />
<inertia ixx="1.3599700899114592099e-05" ixy="2.1015061130866673103e-06"  ixz="-5.2189534392332009867e-07" iyy="3.9845279745643778094e-06" iyz="2.6143361582800957787e-06" izz="1.5058015672984296932e-05" />
</inertial>
</link>

<link name="gear1">
<visual>
<origin xyz="0.051706154054530127639 -0.018788793783707756491 -0.0040000001899898329771" rpy="3.1415926535897926719 -3.8226704713492630234e-16 2.2250548639116183303" />
<geometry>
<mesh filename="package:///grip_finger1.stl"/>
</geometry>
<material name="grip_finger1_material">
<color rgba="0.97254901960784312376 0.52941176470588235947 0.0039215686274509803377 1.0"/>
</material>
</visual>
<collision>
<origin xyz="0.051706154054530127639 -0.018788793783707756491 -0.0040000001899898329771" rpy="3.1415926535897926719 -3.8226704713492630234e-16 2.2250548639116183303" />
<geometry>
<mesh filename="package:///grip_finger1.stl"/>
</geometry>
</collision>
<visual>
<origin xyz="0.010101849188099941423 -0.0012258485766371701731 6.9388939039072283776e-18" rpy="3.141592653589793116 9.8607613152626475676e-32 -5.5511151231257827021e-17" />
<geometry>
<mesh filename="package:///gear1.stl"/>
</geometry>
<material name="gear1_material">
<color rgba="0.91764705882352937127 0.91764705882352937127 0.91764705882352937127 1.0"/>
</material>
</visual>
<collision>
<origin xyz="0.010101849188099941423 -0.0012258485766371701731 6.9388939039072283776e-18" rpy="3.141592653589793116 9.8607613152626475676e-32 -5.5511151231257827021e-17" />
<geometry>
<mesh filename="package:///gear1.stl"/>
</geometry>
</collision>
<inertial>
<origin xyz="0.03587294160980469826 -0.012677501850520215762 -0.0061963370031684530254" rpy="0 0 0"/>
<mass value="0.010048687130952776991" />
<inertia ixx="1.8063743493363531782e-06" ixy="2.7616185740767913626e-06"  ixz="6.2518132543235608893e-07" iyy="6.3900381880004538526e-06" iyz="-2.4920435131392564561e-07" izz="7.9331680776724652248e-06" />
</inertial>
</link>

<joint name="gripper2" type="revolute">
<origin xyz="-0.026899994612884090689 -1.1603107738511475588e-08 0" rpy="3.1415926535897926719 3.6906523200396112737e-16 -2.105064272207324283" />
<parent link="link_palm" />
<child link="gear1" />
<axis xyz="0 0 1"/>
<limit effort="1" velocity="20" />
<joint_properties friction="0.0"/>
</joint>

<joint name="gripper" type="revolute">
<origin xyz="0.0075127824466331531716 0.048986230405415318034 0.042494698429889163349" rpy="-1.570796326794896558 -0 0" />
<parent link="gear2ok" />
<child link="link_palm" />
<axis xyz="0 0 1"/>
<limit effort="1" velocity="20" lower="-1.570796326794896558" upper="0"/>
<joint_properties friction="0.0"/>
</joint>


</robot>
