<robot name="onshape">
    <link name="dummy" />
    <link name="arm3">
        <visual>
            <origin xyz="0.069286642488982447263 -0.0016263012162936727779 0.19372352846538856697" rpy="-1.5707963267951670083 -1.501990478773649107 0.012551015856821223782" />
            <geometry>
                <mesh filename="package://tangs5dof/urdf/arm3.stl" />
            </geometry>
            <material name="arm3_material">
                <color rgba="0.2313725490196078538 0.38039215686274507888 0.7058823529411765163 1.0" />
            </material>
        </visual>
        <collision>
            <origin xyz="0.069286642488982447263 -0.0016263012162936727779 0.19372352846538856697" rpy="-1.5707963267951670083 -1.501990478773649107 0.012551015856821223782" />
            <geometry>
                <mesh filename="package://tangs5dof/urdf/arm3.stl" />
            </geometry>
        </collision>
        <inertial>
            <origin xyz="0.064019560538559075469 0.0070448898543647026083 0.19412482000266378934" rpy="0 0 0" />
            <mass value="0.020616204027974354557" />
            <inertia ixx="3.2534563525259959388e-06" ixy="6.7772788611822073483e-07" ixz="1.2559791444413544244e-07" iyy="6.2859334715843072602e-06" iyz="-5.3051665623261195765e-08" izz="4.8731196883597368349e-06" />
        </inertial>
    </link>
    <joint name="dummy_joint" type="fixed">
        <parent link="dummy" />
        <child link="arm3" />
    </joint>
    <link name="arm2">
        <visual>
            <origin xyz="0.0053075885986863802213 0.013514474980678490082 -0.057500001043081290508" rpy="1.570796326794896558 -0 -6.5027475249219949285e-20" />
            <geometry>
                <mesh filename="package://tangs5dof/urdf/arm2.stl" />
            </geometry>
            <material name="arm2_material">
                <color rgba="0.61568627450980395466 0.81176470588235294379 0.92941176470588238168 1.0" />
            </material>
        </visual>
        <collision>
            <origin xyz="0.0053075885986863802213 0.013514474980678490082 -0.057500001043081290508" rpy="1.570796326794896558 -0 -6.5027475249219949285e-20" />
            <geometry>
                <mesh filename="package://tangs5dof/urdf/arm2.stl" />
            </geometry>
        </collision>
        <inertial>
            <origin xyz="0.0053354610046044024727 0.00011343810143671882729 -0.050485733577047837983" rpy="0 0 0" />
            <mass value="0.052819407015602941324" />
            <inertia ixx="5.7316835569171644879e-05" ixy="6.1035161362994997912e-10" ixz="-7.3935105052967991413e-08" iyy="6.1042835938249356289e-05" iyz="2.896290949500153478e-07" izz="9.7447534283257454779e-06" />
        </inertial>
    </link>
    <link name="arm1">
        <visual>
            <origin xyz="0.057663569884095100537 0.00060194423267771746122 0" rpy="3.387476716188103273e-19 4.8023066144558868637e-19 -1.570796326794896558" />
            <geometry>
                <mesh filename="package://tangs5dof/urdf/arm1.stl" />
            </geometry>
            <material name="arm1_material">
                <color rgba="0.76862745098039220171 0.88627450980392152857 0.95294117647058818044 1.0" />
            </material>
        </visual>
        <collision>
            <origin xyz="0.057663569884095100537 0.00060194423267771746122 0" rpy="3.387476716188103273e-19 4.8023066144558868637e-19 -1.570796326794896558" />
            <geometry>
                <mesh filename="package://tangs5dof/urdf/arm1.stl" />
            </geometry>
        </collision>
        <inertial>
            <origin xyz="0.059200778442978697902 -1.2406768289514542031e-05 0.0077948564897016908368" rpy="0 0 0" />
            <mass value="0.079963772883510669809" />
            <inertia ixx="1.1383675248669571873e-05" ixy="1.0270272944396628538e-09" ixz="2.9902863431550200458e-07" iyy="0.00013379400877519765029" iyz="-2.6825379734458391936e-10" izz="0.00013980580671442963993" />
        </inertial>
    </link>
    <link name="part_1">
        <visual>
            <origin xyz="-0.013965289960663616886 -0.040301559464014063972 0.0040000001899898052216" rpy="-1.570796326794896558 -1.570796326794896558 0" />
            <geometry>
                <mesh filename="package://tangs5dof/urdf/part_1.stl" />
            </geometry>
            <material name="part_1_material">
                <color rgba="0.61568627450980395466 0.81176470588235294379 0.92941176470588238168 1.0" />
            </material>
        </visual>
        <collision>
            <origin xyz="-0.013965289960663616886 -0.040301559464014063972 0.0040000001899898052216" rpy="-1.570796326794896558 -1.570796326794896558 0" />
            <geometry>
                <mesh filename="package://tangs5dof/urdf/part_1.stl" />
            </geometry>
        </collision>
        <inertial>
            <origin xyz="-0.012609627711571943717 -0.023018102601310333477 -0.0024368925816384253216" rpy="0 0 0" />
            <mass value="0.085013969989408674777" />
            <inertia ixx="5.6210967383201727811e-05" ixy="-7.7893279410219734484e-06" ixz="7.9880225262161873533e-07" iyy="6.8281916421221113987e-05" iyz="6.467979915412664117e-06" izz="7.2590632130354267623e-05" />
        </inertial>
    </link>
    <link name="base">
        <visual>
            <origin xyz="0 0 -0.056000001728534698486" rpy="0 -0 0" />
            <geometry>
                <mesh filename="package://tangs5dof/urdf/base.stl" />
            </geometry>
            <material name="base_material">
                <color rgba="0.91764705882352937127 0.91764705882352937127 0.91764705882352937127 1.0" />
            </material>
        </visual>
        <collision>
            <origin xyz="0 0 -0.056000001728534698486" rpy="0 -0 0" />
            <geometry>
                <mesh filename="package://tangs5dof/urdf/base.stl" />
            </geometry>
        </collision>
        <inertial>
            <origin xyz="0.00011682982551327141777 -1.3255133999595796758e-05 -0.033698641155267772263" rpy="0 0 0" />
            <mass value="0.12002083594684367918" />
            <inertia ixx="0.00015985952079173267114" ixy="-1.4995133842184851428e-09" ixz="4.8835847869682253653e-06" iyy="0.00017194770426647181297" iyz="7.4030030502572907204e-10" izz="0.00025973363809823083121" />
        </inertial>
    </link>
    <joint name="shoulder" type="revolute">
        <origin xyz="-0.013965289960663616886 -0.040301559464014063972 0.0040000001899898052216" rpy="-1.570796326794896558 -0.012551015857183739355 -4.1254338333079384561e-23" />
        <parent link="part_1" />
        <child link="base" />
        <axis xyz="0 0 1" />
        <limit effort="1" velocity="20" lower="-1.570796326794896558" upper="1.570796326794896558" />
        <joint_properties friction="0.0" />
    </joint>
    <joint name="elbow" type="revolute">
        <origin xyz="0.11998739918318486464 -2.123187930913594812e-06 -3.4694469519536141888e-18" rpy="-3.3269375668139454439e-15 2.1475876632594051176e-15 1.0742051321332899416" />
        <parent link="arm1" />
        <child link="part_1" />
        <axis xyz="0 0 1" />
        <limit effort="1" velocity="20" lower="0" upper="3.141592653589793116" />
        <joint_properties friction="0.0" />
    </joint>
    <joint name="waist" type="revolute">
        <origin xyz="0.0053082245392913340876 0.0075144749285244241688 -0.089748321005440917508" rpy="1.570796326794896558 -0.56539704268284429745 3.1415926535897891192" />
        <parent link="arm2" />
        <child link="arm1" />
        <axis xyz="0 0 1" />
        <limit effort="1" velocity="20" lower="0" upper="4.712388980384689674" />
        <joint_properties friction="0.0" />
    </joint>
    <joint name="end_effector" type="revolute">
        <origin xyz="0.045824285302664989616 0.01209055363782678659 0.19033089908423339587" rpy="-3.141592653589793116 -1.5019904787736619856 0.012551015857082400279" />
        <parent link="arm3" />
        <child link="arm2" />
        <axis xyz="0 0 1" />
        <limit effort="1" velocity="20" lower="-1.570796326794896558" upper="1.570796326794896558" />
        <joint_properties friction="0.0" />
    </joint>
    <transmission name="trans_shoulder">
        <type>transmission_interface/SimpleTransmission</type>
        <joint name="shoulder">
            <hardwareInterface>hardware_interface/EffortJointInterface</hardwareInterface>
        </joint>
        <actuator name="shoulder_motor">
            <hardwareInterface>hardware_interface/EffortJointInterface</hardwareInterface>
            <mechanicalReduction>1</mechanicalReduction>
        </actuator>
    </transmission>
    <transmission name="trans_elbow">
        <type>transmission_interface/SimpleTransmission</type>
        <joint name="elbow">
            <hardwareInterface>hardware_interface/EffortJointInterface</hardwareInterface>
        </joint>
        <actuator name="elbow_motor">
            <hardwareInterface>hardware_interface/EffortJointInterface</hardwareInterface>
            <mechanicalReduction>1</mechanicalReduction>
        </actuator>
    </transmission>
    <transmission name="trans_waist">
        <type>transmission_interface/SimpleTransmission</type>
        <joint name="waist">
            <hardwareInterface>hardware_interface/EffortJointInterface</hardwareInterface>
        </joint>
        <actuator name="waist_motor">
            <hardwareInterface>hardware_interface/EffortJointInterface</hardwareInterface>
            <mechanicalReduction>1</mechanicalReduction>
        </actuator>
    </transmission>
    <transmission name="trans_end_effector">
        <type>transmission_interface/SimpleTransmission</type>
        <joint name="end_effector">
            <hardwareInterface>hardware_interface/EffortJointInterface</hardwareInterface>
        </joint>
        <actuator name="end_effector_motor">
            <hardwareInterface>hardware_interface/EffortJointInterface</hardwareInterface>
            <mechanicalReduction>1</mechanicalReduction>
        </actuator>
    </transmission>
    <gazebo>
        <plugin name="gazebo_ros_control">
            <robotNamespace>/</robotNamespace>
        </plugin>
    </gazebo>
</robot>

